Workbook

Sheet Master
A1: Activate/Deactivate | B1: Count | C1: Column1 | D1: Object_Type | E1: Old F or T # | F1: Indicator Name | G1: Object ID | H1: Figure ID | I1: Our Data Source | J1: Table # | K1: Primary Data Source | L1: County Assigned
A2: Activate | B2: 1 | D2: Table | E2: T1 | F2: Population Demographic Characteristics, 2023 | G2: tbl-population-demographics | I2: US Census ACS 5-Year | J2: Table S0101 | L2: Orange
A3: Activate | B3: 2 | D3: Table | E3: T2 | F3: Population by Sex, 2023 | G3: tbl-sex | I3: US Census ACS 5-Year | J3: Table S0101 | L3: Orange
A4: Activate | B4: 3 | D4: Table | E4: T3 | F4: Population by Age, 2023 | G4: tbl-age | I4: US Census ACS 5-Year | J4: Table S0101 | L4: Orange
A5: Activate | B5: 4 | D5: Table | E5: T4 | F5: Population by Ethnicity, 2023 | G5: tbl-ethnicity | I5: US Census ACS 5-Year | J5: Table B03002 | L5: Orange
A6: Activate | B6: 5 | D6: Table | E6: T5 | F6: Population by Race, 2023 | G6: tbl-race | I6: US Census ACS 5-Year | J6: Table B03002 | L6: Orange
A7: Activate | B7: 6 | D7: Table | E7: T6 | F7: Population by Spoken Language, 2023 | G7: tbl-language | I7: US Census ACS 5-Year | J7: Table S1601 | L7: Orange
A8: Activate | B8: 7 | D8: Table | E8: T7 | F8: Population 25 Years and Older, 2023 | G8: tbl-pop-25 | I8: US Census ACS 5-Year | J8: Table S1501 | L8: Orange
A9: Activate | B9: 8 | D9: Table | E9: T8 | F9: Population by Educational Attainment, 2023 | G9: tbl-education-base | I9: US Census ACS 5-Year | J9: Table S1501 | L9: Orange
A10: Activate | B10: 9 | D10: Table | E10: T9 | F10: Total Households, 2023 | G10: tbl-households | I10: US Census ACS 5-Year | J10: Table S1901 | L10: Orange
A11: Activate | B11: 10 | D11: Table | E11: T10 | F11: Households by Income, 2023 | G11: tbl-income | I11: US Census ACS 5-Year | J11: Table S1901 | L11: Orange
A12: Activate | B12: 11 | D12: Table | E12: T11 | F12: Population by Veteran Status, 2023 | G12: tbl-veteran | I12: US Census ACS 5-Year | J12: Table S2101 | L12: Orange
A13: Activate | B13: 12 | D13: Table | E13: T12 | F13: Percentage of Population by Type of Disability, 2023 | G13: tbl-disability | I13: US Census ACS 5-Year | J13: Table S1810 | L13: Orange
A14: Activate | B14: 13 | D14: Figure | E14: F1 | F14: Percentage in Labor Force, Population 16 Years and Older, 2021–2023 | G14: tbl-labor-force | H14: fig-labor-force | I14: US Census ACS 5-Year | J14: Table DP03 | L14: Orange
A15: Activate | B15: 14 | D15: Figure | E15: F2 | F15: Percentage of Population Unemployed, 16 Years and Older, 2021-2023 | G15: tbl-unemployed | H15: fig-unemployed | I15: US Census ACS 5-Year | J15: Table DP03 | L15: Orange
A16: Activate | B16: 15 | D16: Figure | E16: F3 | F16: Percentage of Overall Food Insecurity, 2020–2023 | G16: tbl-food-insecurity | H16: fig-food-insecurity | I16: Feeding America | L16: Orange
A17: Activate | B17: 16 | D17: Figure | E17: F4 | F17: Percentage of Food Insecurity, Children 18 Years and Younger, 2020–2023 | G17: tbl-childhood-food-insecurity | H17: fig-childhood-food-insecurity | I17: Feeding America | L17: Orange
A18: Activate | B18: 17 | D18: Figure | E18: F5 | F18: Percentage of Cost Burdened Renter Occupied Units, 2021–2023 | G18: tbl-cost-burdened-renters | H18: fig-cost-burdened-renters | I18: US Census ACS 5-Year | J18: Table DP04 | L18: Orange
A19: Activate | B19: 18 | D19: Figure | E19: F6 | F19: Percentage of Severely Cost Burdened Households, 2016–2023 | G19: tbl-severely-cost-burdened | H19: fig-severely-cost-burdened | I19: County Health Rankings and Roadmaps | K19: US Census ACS 5-Year | L19: Orange
A20: Activate | B20: 19 | D20: Table | E20: T13 | F20: Number of people living in HUD-Subsidized Housing in the Past 12 Months, 2021–2024 | G20: tbl-hud-housing | I20: US Department of Housing and Urban Development | L20: Orange
A21: Activate | B21: 20 | D21: Table | E21: T14 | F21: Poverty Threshold for 2024 by Size of Family and Number of Related Children 18 Years and Younger | G21: tbl-poverty-threshold | I21: US Census | L21: Orange
A22: Activate | B22: 21 | D22: Figure | E22: F7 | F22: Percentage of Population in Poverty, 2021–2023 | G22: tbl-poverty-rate | H22: fig-poverty-rate | I22: US Census ACS 5-Year | J22: Table S1701 | L22: Orange
A23: Activate | B23: 22 | D23: Figure | E23: F8 | F23: Percentage of Families below Poverty by Race and Ethnicity, 2018–2022 | G23: tbl-poverty-by-race | H23: fig-poverty-by-race | I23: NYS County Health Indicators by Race/Ethnicity (CHIRE) | K23: US Census SAIPE | L23: Orange
A24: Activate | B24: 23 | D24: Figure | E24: F9 | F24: Enrollment Rate of Economically Disadvantaged Students, 2021-2023 | G24: tbl-economically-disadvantaged | H24: fig-economically-disadvantaged | I24: NYS Education Department | L24: Orange
A25: Activate | B25: 24 | D25: Table | E25: T15 | F25: ALICE Household Survival Budget, New York State, 2023 | G25: tbl-alice-budget | I25: United for ALICE | L25: Orange
A26: Activate | B26: 25 | D26: Figure | E26: F10 | F26: ALICE Threshold Percentage, 2023 | G26: tbl-alice-threshold | H26: fig-alice-threshold | I26: United for ALICE | L26: Orange
A27: Activate | B27: 26 | D27: Figure | E27: F11 | F27: High School Graduation Rate, 2021-2023 | G27: tbl-graduation-rate | H27: fig-graduation-rate | I27: NYS Education Department | L27: Orange
A28: Activate | B28: 27 | D28: Figure | E28: F12 | F28: High School Graduation Rate, by Race and Ethnicity, 2023 | G28: tbl-graduation-by-race | H28: fig-graduation-by-race | I28: NYS Education Department | L28: Orange
A29: Activate | B29: 28 | D29: Figure | E29: F 13 | F29: Rate of Higher Education Attainment, 2023 | G29: tbl-educational-attainment | H29: fig-educational-attainment | I29: US Census ACS 5-Year | J29: Table S1501 | L29: Orange
A30: Activate | B30: 29 | D30: Figure | E30: F 14 | F30: Percentage of Population that Speaks English "Less Than Very Well", 5 Years and Older, 2021–2023 | G30: tbl-language-proficiency | H30: fig-language-proficiency | I30: US Census ACS 5-Year | J30: Table S1601 | L30: Orange
A31: Activate | B31: 30 | D31: Figure | E31: F15 | F31: Percentage of Disconnected Youth, 16–19 Years Old, 2014–2023 | G31: tbl-disconnected-youth | H31: fig-disconnected-youth | I31: County Health Rankings and Roadmaps | L31: Orange
A32: Activate | B32: 31 | D32: Figure | E32: F16 | F32: Index Score of Residential Segregation, 2013–2023 | G32: tbl-residential-segregation | H32: fig-residential-segregation | I32: County Health Rankings and Roadmaps | L32: Orange
A33: Activate | B33: 32 | D33: Figure | E33: F17 | F33: Percentage of Adults Who Did Not Receive Medical Care Due to Cost, 2016, 2018, and 2021 | G33: tbl-adult-medical-care-cost | H33: fig-medical-care-cost | I33: NYS Behavioral Risk Factor Surveillance System (BRFSS) | L33: Orange
A34: Activate | B34: 33 | D34: Figure | E34: F18 | F34: Percentage of Children Without Health Insurance, 2020–2023 | G34: tbl-children-uninsured | H34: fig-children-uninsured | I34: County Health Rankings and Roadmaps | L34: Orange
A35: Activate | B35: 34 | D35: Figure | E35: F19 | F35: Percentage of Adults with Health Insurance, 2020–2023 | G35: tbl-adult-health-insured | H35: fig-adult-health-insured | I35: US Census | L35: Orange
A36: Activate | B36: 35 | D36: Table | E36: T16 | F36: Medically Underserved Areas and Populations | G36: tbl-medically-underserved | I36: HRSA | J36: Data Warehouse | L36: Orange
A37: Activate | B37: 36 | E37: F20 | F37: Ratio of Residents to Primary Care Providers, 2019–2022 | G37: tbl-primary-care-providers | H37: fig-primary-care-providers | I37: County Health Rankings and Roadmaps | L37: Orange
A38: Activate | B38: 37 | E38: F21 | F38: Ratio of Residents to Dentists, 2019–2022 | G38: tbl-dentists | H38: fig-dentists | I38: County Health Rankings and Roadmaps | L38: Orange
A39: Activate | B39: 38 | E39: F22 | F39: Ratio of Residents to Mental Health Providers, 2021–2024 | G39: tbl-mental-health-providers | H39: fig-mental-health-providers | I39: County Health Rankings and Roadmaps | K39: National Provider Identification Registry, Center for Medicaid and Medicare Services | L39: Orange
A40: Activate | B40: 39 | E40: F23 | F40: Percentage of Adults Who Have a Regular Health Care Provider, 2016, 2018, and 2021 | G40: tbl-adult-access-primary-care | H40: fig-access-to-primary-care | I40: NYS Community Health Indicator Reports (CHIRS) | K40: NYS Behavioral Risk Factor Surveillance System (BRFSS) | L40: Orange
...

Sheet Dropdowns
A1: integer | B1: Y-labels | D1: Footnotes | E1: Sources | F1: Links | G1: Dates | H1: Notes
A2: number | B2: Case Rate | C2: * | D2: *: BRFSS - Crude rate is unreliable due to large standard error. | E2: Source: Centers for Disease Control and Prevention | F2: https://health.data.ny.gov/Health/Behavioral-Risk-Factor-Surveillance-System-BRFSS-H/jsy7-eb4n/data | G2: July 2025 | H2: Note: "Other" includes American Indian or Alaska Native and Native Hawaiian or Other Pacific Islander.
A3: percent1 | B3: Index | C3: * | D3: *: BRFSS - Percentage is unreliable due to large standard error. | E3: Source: Community Partner Survey Focus Groups | F3: https://www.cdc.gov/places/ | G3: June 2025 | H3: Note:A community water system is a public water system that serves the same people year-round. Most residences including homes, apartments, and condominiums in cities, towns, and mobile home parks are served by community water systems. This is a measure of the number of residents served by community water systems with optimal fluoride levels per 100 residents served by community water systems.
A4: percent2 | B4: Number of Cases | C4: * | D4: *: Data are unstable due to a margin of error greater than 10%. | E4: Source: Feeding America | F4: https://webbi1.health.ny.gov/SASStoredProcess/guest?_program=%2FEBI%2FPHIG%2Fapps%2Fchir_dashboard%2Fchir_dashboard&p=ch&cos=33 | G4: May 2025 | H4: Note: County of residence was assigned based on ZIP Code for cases in which patient county of residence was listed as unknown or missing but a valid NY ZIP Code was present.
A5: currency | B5: Percent | C5: * | D5: *: Data are unstable due to fewer than 10 events in the numerator. | E5: Source: Health Resources and Services Administration Data Warehouse | F5: https://www.health.ny.gov/statistics/community/minority/county/orange.htm | G5: April 2025 | H5: Note: Feeding America takes the CPS data and analyzes the relationships between food insecurity and its determinants (i.e., unemployment, poverty, disability, homeownership, and median income), as well as the percentage of the population that is Black and the percentage of the population that is Hispanic. Coefficient estimates from this analysis combined with information on the same variables defined at the county and congressional district levels are generated to estimate food insecurity.
A6: currency2 | B6: Rate per 1,000 | C6: * | D6: *: Data are unstable due to fewer than 20 events in the numerator. | E6: Source: NYC Poison Center | F6: https://www.health.ny.gov/statistics/diseases/communicable/docs/2019_hepc_regional.pdf | G6: March 2025 | H6: Note: Five-year age-adjusted rates.
A7: ratio | B7: Rate per 10,000 | C7: * | D7: *: The percentage is unstable. | E7: Source: NYS Board of Elections | F7: https://www.health.ny.gov/statistics/chac/perinatal/county/2018-2020/orange.htm | G7: February 2025 | H7: Note: IMU* = Index of Medical Underservice.
A8: date | B8: Rate per 100,000 | C8: * | D8: *: The rate is unstable. | E8: Source: NYS Cancer Registry and Cancer Statistics | F8: https://www.criminaljustice.ny.gov/crimnet/ojsa/arrests/index.htm | G8: January 2025 | H8: Note: Incidence and mortality rates stratified by race/ethnicity are not available. However, trend data for incidence and mortality rates can be found on NYSDOH Community Health Indicator Reports (CHIRS).
B9: Ratio | C9: + | D9: : The 2019 ED data in NYC may be incomplete and subject to change. Thus, the state rates may be underestimated and subject to change. | E9: Source: NYS Community Health Indicator Reports Dashboard | F9: https://data.nysed.gov/gradrate.php?year=2022&county=44 | G9: December 2024 | H9: Note: Incidence and mortality rates stratified by race/ethnicity are not shown due to suppressed and/or unstable data in most counties. However, trend data for incidence and mortality rates can be found on NYSDOH Community Health Indicator Reports (CHIRS).
C10: Other | D10: Other (please specify): Some additional responses from participants include access to healthy affordable food, transportation, valuing health as a family priority, affordable housing, lack of chronic disease self-management programs, lack of social support systems, language barriers. | E10: Source: NYS County Health Indicators by Race and Ethnicity | F10: https://webbi1.health.ny.gov/SASStoredProcess/guest?_program=%2FEBI%2FPHIG%2Fapps%2Fmch_dashboard%2Fmch_dashboard&p=ch&cos=33 | G10: November 2024 | H10: Note: Index of dissimilarity where higher values indicate greater residential segregation between Black and White County residents.
C11: Other | D11: Other (please specify): Some additional responses from participants include finding child care, access to health care providers who are trained in LGBTQIA+ health care needs, mental health services, immigration issues, language and cultural barriers, and financial issues. | E11: Source: NYS Department of Health Office of Sexual Health and Epidemiology | F11: https://webbi1.health.ny.gov/SASStoredProcess/guest?_program=%2FEBI%2FPHIG%2Fapps%2Fopioid_dashboard%2Fop_dashboard&p=ch&cos=33 | G11: October 2024 | H11: Note: Mortality rates stratified by race/ethnicity are not available.
C12: Other | D12: Other (please specify): Some additional responses from participants include location of services, lack of financial resources, transportation, affordable housing, and service providers not being aware of biases they bring into marginalized communities. | E12: Source: NYS Division of Criminal Justice Services | F12: https://webbi1.health.ny.gov/SASStoredProcess/guest?_program=%2FEBI%2FPHIG%2Fapps%2Fdashboard%2Fpa_dashboard&p=ch&cos=33 | G12: September 2024 | H12: Note: Opioid pain relievers include illicitly produced opioids such as fentanyl.
C13: Other | D13: Other (please specify): Some additional responses from participants include navigating health care access, poverty, affordable transportation, and accessibility and availability of quality services. | E13: Source: NYS Education Department | F13: https://www.health.ny.gov/statistics/diseases/communicable/std/docs/sti_surveillance_report_2021.pdf | G13: August 2024 | H13: Note: Other forms of coverage not shown include Indian Health, CHAMPUS, Other, and Not Stated. Medicaid includes births with Medicaid listed as secondary payer.
C14: Other | D14: Other (please specify): Some additional responses from participants include stigma, language barrier as a large portion of the population being served speaks Spanish, navigating the health system, and places to play and/or exercise. | E14: Source: NYS Leading Causes of Death Dashboard | F14: https://statecancerprofiles.cancer.gov/ | G14: July 2024 | H14: Note: Race or races with which the student primarily identifies are indicated by the student or the parent/guardian.
C15: s | D15: s: Data are suppressed due to unreliable or missing data. | E15: Source: NYS Opioid Data Dashboard | F15: https://data.census.gov/cedsci/ | G15: June 2024 | H15: Note: Ranks are based on numbers of deaths, then on mortality rates.
C16: s | D16: s: Data are suppressed due to not meeting reporting criteria. | E16: Source: NYS Prevention Agenda Tracking Dashboard | F16: https://www.americashealthrankings.org/ | G16: May 2024 | H16: Note: Respondents who report any one of the six disability types are considered to have a disability in the American Community Survey. The previous Regional CHA utilized data from the NYSDOH Expanded Behavioral Risk Factor Surveillance System (BRFSS). The data change between the BRFSS and the ACS accounts for the drastic changes between the Regional CHAs.
C17: s | D17: s: Data are suppressed due to lack of preliminary data. | E17: Source: NYS Smoker's Quitline | F17: https://ahead.hiv.gov/ | G17: April 2024 | H17: Note: Severely cost burdened is defined as the percent of households that spend 50% or more of their household income on housing. The 2019 County Health Rankings (CHR) used data from 2013-2017 and the 2022 CHR used data from 2016-2020 for this measure.
C18: s | D18: s: Data are suppressed due to not meeting confidentialty criteria. | E18: Source: NYSDOH Behavioral Risk Factor Surveillance System | F18: https://wonder.cdc.gov/ | G18: March 2024 | H18: Note: Single-year crude rates.
C19: s | D19: s: Data are suppressed due to small sample size. | E19: Source: NYSDOH Bureau of Communicable Disease Control | F19: https://nccd.cdc.gov/Youthonline/App/Results.aspx?LID=XX | G19: February 2024 | H19: Note: The American Community Survey asks respondents how many automobiles, vans, and trucks of one-ton capacity or less are kept at home for use by members of the household.
E20: Source: NYSDOH Communicable Disease Annual Reports | F20: https://www.cdc.gov/injury/wisqars/index.html | G20: January 2024 | H20: Note: The American Community Survey asks respondents how they usually got to work last week. For respondents who use multiple transportation modes they are restricted to the single method of transportation used for the longest distance.
E21: Source: NYSDOH Communicable Disease Electronic Surveillance System | F21: https://www.cdc.gov/mmwr/index.html | G21: December 2023 | H21: Note: The American Community Survey asks respondents if they have ever served on active duty in the US Armed Forces.
E22: Source: NYSDOH, Wadsworth Center Rabies Laboratory | F22: https://www.cdc.gov/asthma/asthmadata.htm | G22: November 2023 | H22: Note: The American Community Survey asks respondents if they have worked in the past week. If the answer is no, they are asked why they are not working. For those who are not working, they are asked whether they plan to return to work, and when they last worked.
E23: Source: United for ALICE | F23: https://www.cdc.gov/nceh/ | G23: October 2023 | H23: Note: The American Community Survey asks respondents if they own or rent the house, apartment, or mobile home they live in. If rented, they ask the monthly rent. Cost burdened is defined as the percentage of renter occupied units in which gross rent is 30% or more of household income.
E24: Source: University of Wisconsin Population Health Institute. County Health Rankings & Roadmaps | F24: https://www.cdc.gov/nchs/index.htm | G24: September 2023 | H24: Note: The American Community Survey asks respondents in the workforce how many minutes it usually takes them to get from home to work. The travel time refers to a one-way trip on a typical day. This includes time spent waiting for public transportation, picking up passengers in carpools, and time spent in other activities related to getting to work.
E25: Source: Upstate NY Poison Center | F25: https://www.cdc.gov/nchs/nhis/shs.htm | G25: August 2023 | H25: Note: The American Community Survey asks respondents their income in the past 12 months including joint income. This is for income that is received on a regular basis before payments for taxes, social security, etc. If a family’s total income is less than the official poverty threshold for a family of that size and composition, they are considered to be in poverty.
E26: Source: US Census Bureau | F26: https://www.cdc.gov/diabetes/data/index.html | G26: July 2023 | H26: Note: The American Community Survey asks respondents their income in the past 12 months. Data are provided as a percent of total households in Table S1901. Calculations were made to provide data as a number in Table 28.
E27: Source: US Census Bureau; American Community Survey | F27: https://www.cdc.gov/nchhstp/atlas/index.htm | G27: June 2023 | H27: Note: The American Community Survey asks respondents to report whether they sometimes or always spoke a language other than English at home. People who knew languages other than English but did not use them at home, who only used them elsewhere, or whose usage was limited to a few expressions or slang were excluded.
E28: Source: Vital Statistics of NYS | F28: https://www.cdc.gov/std/statistics/2021/default.htm | G28: May 2023 | H28: Note: The American Community Survey asks respondents what the highest degree or level of school the person has completed.
F29: https://www.cdc.gov/vaccines/imz-managers/coverage/teenvaxview/data-reports/index.html | G29: April 2023 | H29: Note: The American Community Survey includes a question that intends to capture current sex; there are no questions about gender, sexual orientation, or sex at birth. Respondents should respond either "male" or "female" based on how they currently identify their sex.
F30: https://gis.cdc.gov/grasp/diabetes/diabetesatlas-surveillance.html | G30: March 2023 | H30: Note: The American Community Survey utilized industry titles based on the North American Industry Classification System from 2018.
F31: https://www.cdc.gov/hepatitis/statistics/SurveillanceRpts.htm | G31: February 2023 | H31: Note: The Census Bureau collects racial data in accordance with guidelines provide by the US Office of Management and Budget, and these data are based on self-identification. People who identify with more than one race may choose to provide multiple races in response to the race question. For ethnicity, the OMB standards classify individuals in one of two categories: “Hispanic or Latino” or “Not Hispanic or Latino.” The Census Bureau uses the term “Hispanic or Latino” interchangeably with the term “Hispanic,” and also refer to this concept as “ethnicity.”
F32: https://www.ghrconnects.org/indicators | G32: January 2023 | H32: Note: The Census Bureau collects racial data in accordance with guidelines provided by the US Office of Management and Budget (OMB) and these data are based on self-identification. People who identify with more than one race may choose to provide multiple races in response to the race question. For ethnicity, the OMB standards classify individuals in one of two categories: “Hispanic or Latino” or “Not Hispanic or Latino.” The Census Bureau uses the term “Hispanic or Latino” interchangeably with the term “Hispanic,” and also refer to this concept as “ethnicity.” The American Community Survey asks respondents their income in the past 12 months including joint income. This is for income that is received on a regular basis before payments for taxes, social security, etc. If a family’s total income is less than the official poverty threshold for a family of that size and composition, then they are considered to be in poverty.
F33: https://www.kff.org/ | G33: December 2022 | H33: Note: The Census Bureau defines educational attainment as the highest level of education that an individual has completed. This is distinct from the level of schooling that an individual is attending.
F34: https://progressreport.cancer.gov/detection | G34: November 2022 | H34: Note: The most recent data are from 2019.
F35: https://statecancerprofiles.cancer.gov/index.html | G35: October 2022 | H35: Note: The number of cases is determined using sentinel surveillance, which is extrapolated from samples of positive laboratory results to generate estimates of the total number of cases. Sentinel surveillance was conducted in all Mid-Hudson counties in 2017.
F36: https://nces.ed.gov/ | G36: September 2022 | H36: Note: The overall violent crime rate of a county is calculated by dividing the total number of violent crimes submitted by police agencies in each county by the county’s population and multiplying the result by 100,000. The US Census Bureau is the source of county population data. Includes all reports received as of May 16, 2022.
F37: https://www.niaaa.nih.gov/ | G37: August 2022 | H37: Note: The previous Mid-Hudson Region Community Health Assessment, 2019-2021, reported this data on populations aged 5-17 years.
F38: https://data.oecd.org/ | G38: July 2022 | H38: Note: The rate for 2015 is excluded due to SPARCS data transitioning on October 1, 2015 from ICD-9-CM to ICD-10-CM diagnosis codes. Since ICD-9-CM and ICD-10-CM are not comparable, an annual rate for 2015 cannot be calculated, and data for 2016-andforward should not be compared with data for 2014-and-prior.
F39: https://data.census.gov/cedsci/ | G39: June 2022 | H39: Note: The rate for 2015 is excluded due to SPARCS data transitioning on October 1, 2015, from ICD-9-CM to ICD-10-CM diagnosis codes. Since ICD-9-CM and ICD-10-CM are not comparable, an annual rate for 2015 cannot be calculated, and data for 2016-andforward should not be compared with data for 2014-and-prior.
F40: https://www.bls.gov/cps/data-overview.htm | G40: May 2022 | H40: Note: The US Census asks respondents if they are currently covered by any type of health insurance or health coverage plans.
...

Sheet _Demographics

Sheet Population Demographic Characte
A1: Name | B1: Population Demographic Characteristics, 2023
A2: Table/Figure/Both | B2: Table
A3: Object ID | B3: tbl-population-demographics
G4: integer | H4: percent1 | I4: percent1
A5: Table Rules | E5: Enter Data | F5: County | G5: Total Population | H5: Percent of Mid-Hudson Region | I5: Percent of NYS
A6: Multilevel Headers | F6: Dutchess | G6: 297144 | H6: 12.4 | I6: 1.5
A7: Data Type | F7: Orange | G7: 403840 | H7: 16.9 | I7: 2
F8: Putnam | G8: 97988 | H8: 4.1 | I8: 0.5
A9: Figure Rules | F9: Rockland | G9: 338936 | H9: 14.1 | I9: 1.7
A10: Figure Type | F10: Sullivan | G10: 79147 | H10: 3.3 | I10: 0.4
A11: X Column | F11: Ulster | G11: 182109 | H11: 7.6 | I11: 0.9
A12: Y Column | F12: Westchester | G12: 996888 | H12: 41.6 | I12: 5
A13: X Axis Title | F13: Mid-Hudson | G13: 2396052 | H13: 100 | I13: 12.1
A14: Y Axis Title | F14: NYS excl NYC | G14: 11356117 | H14: N/A | I14: 57.1
A15: Start at Zero | F15: NYS | G15: 19872318 | H15: N/A | I15: 100
A18: Source Specifications
A19: Table ID
A20: URL
A21: Data Year
A22: Estimate Type
A23: Citation Month
A24: Citation Year
A25: Custom Text
A27: Note Specfications

Sheet Sex-Population
A1: Name | B1: Population by Sex, 2023
A2: Table/Figure/Both | B2: Table
A3: Object ID | B3: =IF($B$1="","",_xlfn.XLOOKUP($B$1,Master!$F$2:$F$308,Master!$G$2:$G$308,"")) -> tbl-sex
G4: integer | H4: percent1 | I4: integer | J4: percent1
A5: Table Rules | E5: Enter Data | F5: Area | G5: Male | I5: Female
A6: Multilevel Headers | B6: TRUE | G6: Total Population | H6: % | I6: Total Population | J6: %
F7: Dutchess | G7: 147902 | H7: 49.8 | I7: 149242 | J7: 50.2
F8: Orange | G8: 201512 | H8: 49.9 | I8: 202328 | J8: 50.1
A9: Figure Rules | F9: Putnam | G9: 49503 | H9: 50.5 | I9: 48485 | J9: 49.5
A10: Figure Type | F10: Rockland | G10: 167624 | H10: 49.5 | I10: 171312 | J10: 50.5
A11: X Column | F11: Sullivan | G11: 40993 | H11: 51.8 | I11: 38154 | J11: 48.2
A12: Y Column | F12: Ulster | G12: 90719 | H12: 49.8 | I12: 91390 | J12: 50.2
A13: X Axis Title | F13: Westchester | G13: 485985 | H13: 48.8 | I13: 510903 | J13: 51.2
A14: Y Axis Title | F14: Mid-Hudson | G14: 1184238 | H14: 49.4 | I14: 1211814 | J14: 50.6
A15: Start at Zero | F15: NYS excl NYC | G15: 5614391 | H15: 49.4 | I15: 5741726 | J15: 50.6
F16: NYS | G16: 9702417 | H16: 48.8 | I16: 10169902 | J16: 51.2
A18: Source Specifications
A19: Table ID
A20: URL
A21: Data Year
A22: Estimate Type
A23: Citation Month
A24: Citation Year
A25: Custom Text
A27: Note Specfications

Sheet Age-Population
A1: Name | B1: Population by Age, 2023
A2: Table/Figure/Both | B2: Table
A3: Object ID | B3: =IF($B$1="","",_xlfn.XLOOKUP($B$1,Master!$F$2:$F$308,Master!$G$2:$G$308,"")) -> tbl-age
G4: integer | H4: percent1 | I4: integer | J4: percent1 | K4: integer | L4: percent1 | M4: integer | N4: percent1 | O4: integer | P4: percent1 | Q4: integer | R4: percent1 | S4: integer | T4: percent1 | U4: integer | V4: percent1 | W4: integer | X4: percent1 | Y4: integer | Z4: percent1 | AA4: integer | AB4: percent1
A5: Table Rules | E5: Enter Data | G5: <5 years | I5: 5-9 years | K5: 10-19 years | M5: 20-29 years | O5: 30-39 years | Q5: 40-49 years | S5: 50-59 years | U5: 60-69 years | W5: 70-79 years | Y5: >80 years | AA5: <18 years
A6: Multilevel Headers | B6: TRUE | G6: Total Population | H6: % | I6: Total Population | J6: % | K6: Total Population | L6: % | M6: Total Population | N6: % | O6: Total Population | P6: % | Q6: Total Population | R6: % | S6: Total Population | T6: % | U6: Total Population | V6: % | W6: Total Population | X6: % | Y6: Total Population | Z6: % | AA6: Total Population | AB6: %
A7: Data Type | B7: Percent | F7: Dutchess | G7: 13613 | H7: 4.6 | I7: 14448 | J7: 4.9 | K7: 37031 | L7: 12.5 | M7: 38178 | N7: 12.8 | O7: 35520 | P7: 12 | Q7: 36796 | R7: 12.4 | S7: 43025 | T7: 14.5 | U7: 41707 | V7: 14 | W7: 23935 | X7: 8.1 | Y7: 12891 | Z7: 4.3 | AA7: 55342 | AB7: 18.6
F8: Orange | G8: 27143 | H8: 6.7 | I8: 27679 | J8: 6.9 | K8: 61718 | L8: 15.3 | M8: 52658 | N8: 13 | O8: 48459 | P8: 12 | Q8: 49782 | R8: 12.3 | S8: 52995 | T8: 13.1 | U8: 45285 | V8: 11.2 | W8: 25081 | X8: 6.2 | Y8: 13040 | Z8: 3.2 | AA8: 103740 | AB8: 25.7
A9: Figure Rules | F9: Putnam | G9: 4521 | H9: 4.6 | I9: 4320 | J9: 4.4 | K9: 12426 | L9: 12.7 | M9: 10922 | N9: 11.1 | O9: 11264 | P9: 11.5 | Q9: 13032 | R9: 13.3 | S9: 15538 | T9: 15.9 | U9: 13386 | V9: 13.7 | W9: 8739 | X9: 8.9 | Y9: 3840 | Z9: 3.9 | AA9: 19180 | AB9: 19.6
A10: Figure Type | F10: Rockland | G10: 28957 | H10: 8.5 | I10: 27051 | J10: 8 | K10: 52692 | L10: 15.5 | M10: 41742 | N10: 12.3 | O10: 38885 | P10: 11.5 | Q10: 36560 | R10: 10.8 | S10: 40115 | T10: 11.8 | U10: 35529 | V10: 10.5 | W10: 23713 | X10: 7 | Y10: 13692 | Z10: 4 | AA10: 99733 | AB10: 29.4
A11: X Column | F11: Sullivan | G11: 4656 | H11: 5.9 | I11: 4969 | J11: 6.3 | K11: 9343 | L11: 11.8 | M11: 9032 | N11: 11.4 | O11: 9668 | P11: 12.2 | Q11: 9486 | R11: 12 | S11: 11009 | T11: 13.9 | U11: 10980 | V11: 13.9 | W11: 7087 | X11: 9 | Y11: 2917 | Z11: 3.7 | AA11: 16947 | AB11: 21.4
A12: Y Column | F12: Ulster | G12: 7926 | H12: 4.4 | I12: 8802 | J12: 4.8 | K12: 19831 | L12: 10.9 | M12: 22175 | N12: 12.2 | O12: 23060 | P12: 12.7 | Q12: 22177 | R12: 12.2 | S12: 26342 | T12: 14.5 | U12: 26250 | V12: 14.4 | W12: 16546 | X12: 9.1 | Y12: 9000 | Z12: 4.9 | AA12: 31636 | AB12: 17.4
A13: X Axis Title | F13: Westchester | G13: 53282 | H13: 5.3 | I13: 57324 | J13: 5.8 | K13: 129780 | L13: 13 | M13: 115269 | N13: 11.6 | O13: 121312 | P13: 12.2 | Q13: 133617 | R13: 13.4 | S13: 141210 | T13: 14.2 | U13: 121875 | V13: 12.2 | W13: 74727 | X13: 7.5 | Y13: 48492 | Z13: 4.9 | AA13: 214739 | AB13: 21.5
A14: Y Axis Title | F14: Mid-Hudson | G14: 140098 | H14: 5.8 | I14: 144593 | J14: 6 | K14: 322821 | L14: 13.5 | M14: 289976 | N14: 12.1 | O14: 288168 | P14: 12 | Q14: 301450 | R14: 12.6 | S14: 330234 | T14: 13.8 | U14: 295012 | V14: 12.3 | W14: 179828 | X14: 7.5 | Y14: 103872 | Z14: 4.3 | AA14: 541317 | AB14: 22.6
A15: Start at Zero | F15: NYS excl NYC | G15: 604728 | H15: 5.3 | I15: 640751 | J15: 5.6 | K15: 1454784 | L15: 12.8 | M15: 1442397 | N15: 12.7 | O15: 1393651 | P15: 12.3 | Q15: 1343897 | R15: 11.8 | S15: 1566110 | T15: 13.8 | U15: 1485429 | V15: 13.1 | W15: 919800 | X15: 8.1 | Y15: 504570 | Z15: 4.4 | AA15: 2369080 | AB15: 20.9
F16: NYS | G16: 1102961 | H16: 5.6 | I16: 1102946 | J16: 5.6 | K16: 2413200 | L16: 12.1 | M16: 2658703 | N16: 13.4 | O16: 2751639 | P16: 13.8 | Q16: 2422399 | R16: 12.2 | S16: 2638363 | T16: 13.3 | U16: 2425309 | V16: 12.2 | W16: 1511287 | X16: 7.6 | Y16: 845512 | Z16: 4.3 | AA16: 4109277 | AB16: 20.7
A18: Source Specifications
A19: Table ID
A20: URL
A21: Data Year
A22: Estimate Type
A23: Citation Month
A24: Citation Year
A25: Custom Text
A27: Note Specfications

Sheet Ethnicity-Population
A1: Name | B1: Population by Ethnicity, 2023
A2: Table/Figure/Both | B2: Table
A3: Object ID | B3: =IF($B$1="","",_xlfn.XLOOKUP($B$1,Master!$F$2:$F$308,Master!$G$2:$G$308,"")) -> tbl-ethnicity
G4: integer | H4: percent1 | I4: integer | J4: percent1
A5: Table Rules | E5: Enter Data | F5: Area | G5: Hispanic | I5: Non-Hispanic
A6: Multilevel Headers | B6: TRUE | G6: Total Population | H6: % | I6: Total Population | J6: %
A7: Data Type | B7: Percent | F7: Dutchess | G7: 44153 | H7: 14.9 | I7: 252991 | J7: 85.1
F8: Orange | G8: 93608 | H8: 23.2 | I8: 310232 | J8: 76.8
A9: Figure Rules | F9: Putnam | G9: 18676 | H9: 19.1 | I9: 79312 | J9: 80.9
A10: Figure Type | F10: Rockland | G10: 67951 | H10: 20 | I10: 270985 | J10: 80
A11: X Column | F11: Sullivan | G11: 14544 | H11: 18.4 | I11: 64603 | J11: 81.6
A12: Y Column | F12: Ulster | G12: 21562 | H12: 11.8 | I12: 160547 | J12: 88.2
A13: X Axis Title | F13: Westchester | G13: 269085 | H13: 27 | I13: 727803 | J13: 73
A14: Y Axis Title | F14: Mid-Hudson | G14: 529579 | H14: 22.1 | I14: 1866473 | J14: 77.9
A15: Start at Zero | F15: NYS excl NYC | G15: 1478113 | H15: 13 | I15: 9878004 | J15: 87
F16: NYS | G16: 3898652 | H16: 19.6 | I16: 15973667 | J16: 80.4
A18: Source Specifications
A19: Table ID
A20: URL
A21: Data Year
A22: Estimate Type
A23: Citation Month
A24: Citation Year
A25: Custom Text
A27: Note Specfications

Sheet Race-Population
A1: Name | B1: Population by Race, 2023
A2: Table/Figure/Both | B2: Table
A3: Object ID | B3: =IF($B$1="","",_xlfn.XLOOKUP($B$1,Master!$F$2:$F$308,Master!$G$2:$G$308,"")) -> tbl-race
G4: integer | H4: percent1 | I4: integer | J4: percent1 | K4: integer | L4: percent2 | M4: integer | N4: percent1 | O4: integer | P4: percent2 | Q4: integer | R4: percent2 | S4: integer | T4: percent1
A5: Table Rules | E5: Enter Data | F5: Area | G5: Non-Hispanic White | I5: Non-Hispanic Black or African American | K5: Non-Hispanic American Indian and Alaskan Native | M5: Non-Hispanic Asian | O5: Non-Hispanic Native Hawaiian and Other Pacific Islander | Q5: Non-Hispanic Other | S5: Non-Hispanic Two or More Races
A6: Multilevel Headers | B6: TRUE | G6: Total Population | H6: % | I6: Total Population | J6: % | K6: Total Population | L6: % | M6: Total Population | N6: % | O6: Total Population | P6: % | Q6: Total Population | R6: % | S6: Total Population | T6: %
F7: Dutchess | G7: 199670 | H7: 67.2 | I7: 28024 | J7: 9.4 | K7: 222 | L7: 0.07 | M7: 10044 | N7: 3.4 | O7: 117 | P7: 0.04 | Q7: 2206 | R7: 0.7 | S7: 12708 | T7: 4.3
F8: Orange | G8: 239186 | H8: 59.2 | I8: 42478 | J8: 10.5 | K8: 438 | L8: 0.11 | M8: 11223 | N8: 2.8 | O8: 26 | P8: 0.01 | Q8: 2563 | R8: 0.6 | S8: 14318 | T8: 3.5
A9: Figure Rules | F9: Putnam | G9: 70948 | H9: 72.4 | I9: 2894 | J9: 3 | K9: 81 | L9: 0.08 | M9: 2255 | N9: 2.3 | O9: 24 | P9: 0.02 | Q9: 788 | R9: 0.8 | S9: 2322 | T9: 2.4
A10: Figure Type | F10: Rockland | G10: 205539 | H10: 60.6 | I10: 35626 | J10: 10.5 | K10: 181 | L10: 0.05 | M10: 19772 | N10: 5.8 | O10: 38 | P10: 0.01 | Q10: 1921 | R10: 0.6 | S10: 7908 | T10: 2.3
A11: X Column | F11: Sullivan | G11: 53145 | H11: 67.1 | I11: 6263 | J11: 7.9 | K11: 120 | L11: 0.15 | M11: 1584 | N11: 2 | O11: 11 | P11: 0.01 | Q11: 533 | R11: 0.7 | S11: 2947 | T11: 3.7
A12: Y Column | F12: Ulster | G12: 133874 | H12: 73.5 | I12: 10347 | J12: 5.7 | K12: 66 | L12: 0.04 | M12: 3675 | N12: 2 | O12: 40 | P12: 0.02 | Q12: 2242 | R12: 1.2 | S12: 10303 | T12: 5.7
A13: X Axis Title | F13: Westchester | G13: 498855 | H13: 50 | I13: 128199 | J13: 12.9 | K13: 1197 | L13: 0.12 | M13: 59912 | N13: 6 | O13: 96 | P13: 0.01 | Q13: 10638 | R13: 1.1 | S13: 28906 | T13: 2.9
A14: Y Axis Title | F14: Mid-Hudson | G14: 1401217 | H14: 58.5 | I14: 253831 | J14: 10.6 | K14: 2305 | L14: 0.1 | M14: 108465 | N14: 4.5 | O14: 352 | P14: 0.01 | Q14: 20891 | R14: 0.9 | S14: 79412 | T14: 3.3
A15: Start at Zero | F15: NYS excl NYC | G15: 7942876 | H15: 69.9 | I15: 934322 | J15: 8.2 | K15: 21069 | L15: 0.19 | M15: 518716 | N15: 4.6 | O15: 2610 | P15: 0.02 | Q15: 70553 | R15: 0.6 | S15: 387858 | T15: 3.4
F16: NYS | G16: 10608842 | H16: 53.4 | I16: 2708094 | J16: 13.6 | K16: 37212 | L16: 0.19 | M16: 1754957 | N16: 8.8 | O16: 6220 | P16: 0.03 | Q16: 178956 | R16: 0.9 | S16: 679386 | T16: 3.4
A18: Source Specifications
A19: Table ID
A20: URL
A21: Data Year
A22: Estimate Type
A23: Citation Month
A24: Citation Year
A25: Custom Text
A27: Note Specfications

Sheet Spoken Lang-Population
A1: Name | B1: Population by Spoken Language, 2023
A2: Table/Figure/Both | B2: Table
A3: Object ID | B3: =IF($B$1="","",_xlfn.XLOOKUP($B$1,Master!$F$2:$F$308,Master!$G$2:$G$308,"")) -> tbl-language
G4: integer | H4: percent1 | I4: integer | J4: percent1 | K4: integer | L4: percent1 | M4: integer | N4: percent1 | O4: integer | P4: percent1 | Q4: integer | R4: percent2
A5: Table Rules | E5: Enter Data | F5: Area | G5: Only English | I5: Language other than English | K5: Spanish | M5: Other Indo-European languages | O5: Asian and Pacific Islander languages | Q5: Other languages
A6: Multilevel Headers | B6: TRUE | G6: Total Population | H6: % | I6: Total Population | J6: % | K6: Total Population | L6: % | M6: Total Population | N6: % | O6: Total Population | P6: % | Q6: Total Population | R6: %
F7: Dutchess | G7: 238585 | H7: 84.1 | I7: 44946 | J7: 15.9 | K7: 26003 | L7: 9.2 | M7: 10769 | N7: 3.8 | O7: 5267 | P7: 1.9 | Q7: 2907 | R7: 1
F8: Orange | G8: 266545 | H8: 70.8 | I8: 110152 | J8: 29.2 | K8: 55418 | L8: 15 | M8: 45346 | N8: 12 | O8: 6298 | P8: 1.7 | Q8: 3090 | R8: 0.8
A9: Figure Rules | F9: Putnam | G9: 73860 | H9: 79 | I9: 19607 | J9: 21 | K9: 11733 | L9: 13 | M9: 5687 | N9: 6.1 | O9: 1504 | P9: 1.6 | Q9: 683 | R9: 0.7
A10: Figure Type | F10: Rockland | G10: 174907 | H10: 56.4 | I10: 135072 | J10: 43.6 | K10: 46360 | L10: 15 | M10: 69600 | N10: 22.5 | O10: 12024 | P10: 3.9 | Q10: 7088 | R10: 2.3
A11: X Column | F11: Sullivan | G11: 59484 | H11: 79.9 | I11: 15007 | J11: 20.1 | K11: 8639 | L11: 12 | M11: 4877 | N11: 6.5 | O11: 819 | P11: 1.1 | Q11: 672 | R11: 0.9
A12: Y Column | F12: Ulster | G12: 152966 | H12: 87.8 | I12: 21217 | J12: 12.2 | K12: 11924 | L12: 6.8 | M12: 5602 | N12: 3.2 | O12: 2679 | P12: 1.5 | Q12: 1012 | R12: 0.6
A13: X Axis Title | F13: Westchester | G13: 619503 | H13: 65.7 | I13: 324103 | J13: 34.3 | K13: 196271 | L13: 21 | M13: 78915 | N13: 8.4 | O13: 32889 | P13: 3.5 | Q13: 16028 | R13: 1.7
A14: Y Axis Title | F14: Mid-Hudson | G14: 1585850 | H14: 54.2 | I14: 670104 | J14: 22.9 | K14: 356348 | L14: 12.2 | M14: 220796 | N14: 7.5 | O14: 61480 | P14: 2.1 | Q14: 31480 | R14: 1.1
A15: Start at Zero | F15: NYS excl NYC | G15: 8808643 | H15: 69.4 | I15: 1942746 | J15: 15.3 | K15: 940527 | L15: 12.2 | M15: 632717 | N15: 5 | O15: 258104 | P15: 2 | Q15: 111398 | R15: 0.9
F16: NYS | G16: 13017480 | H16: 69.4 | I16: 5751878 | J16: 30.6 | K16: 2762664 | L16: 15 | M16: 1679571 | N16: 8.9 | O16: 958133 | P16: 5.1 | Q16: 351510 | R16: 1.9
A18: Source Specifications
A19: Table ID
A20: URL
A21: Data Year
A22: Estimate Type
A23: Citation Month
A24: Citation Year
A25: Custom Text
A27: Note Specfications

Sheet 25 Years+-Population
A1: Name | B1: Population 25 Years and Older, 2023
A2: Table/Figure/Both | B2: Table
A3: Object ID | B3: =IF($B$1="","",_xlfn.XLOOKUP($B$1,Master!$F$2:$F$308,Master!$G$2:$G$308,"")) -> tbl-pop-25
G4: integer
A5: Table Rules | E5: Enter Data | F5: Area | G5: Total Population
A6: Multilevel Headers | B6: FALSE | F6: Dutchess | G6: 211380
F7: Orange | G7: 258632
F8: Putnam | G8: 71149
A9: Figure Rules | F9: Rockland | G9: 208594
A10: Figure Type | F10: Sullivan | G10: 55761
A11: X Column | F11: Ulster | G11: 134325
A12: Y Column | F12: Westchester | G12: 697202
A13: X Axis Title | F13: Mid-Hudson | G13: 1637043
A14: Y Axis Title | F14: NYS excl NYC | G14: 7905485
A15: Start at Zero | F15: NYS | G15: 13996138
A18: Source Specifications
A19: Table ID
A20: URL
A21: Data Year
A22: Estimate Type
A23: Citation Month
A24: Citation Year
A25: Custom Text
A27: Note Specfications

Sheet Educational Attainment-Pop
A1: Name | B1: Population by Educational Attainment, 2023
A2: Table/Figure/Both | B2: Table
A3: Object ID | B3: =IF($B$1="","",_xlfn.XLOOKUP($B$1,Master!$F$2:$F$308,Master!$G$2:$G$308,"")) -> tbl-education-base
G4: integer | H4: percent1 | I4: integer | J4: percent1 | K4: integer | L4: percent1 | M4: integer | N4: percent1 | O4: integer | P4: percent1 | Q4: integer | R4: percent1 | S4: integer | T4: percent1
A5: Table Rules | E5: Enter Data | F5: Area | G5: Less than 9th grade | I5: 9th to 12th grade, no diploma | K5: High school graduate or equivalent | M5: Some college, no degree | O5: Associate degree | Q5: Bachelor's degree | S5: Graduate or professional degree
A6: Multilevel Headers | B6: TRUE | G6: N | H6: % | I6: N | J6: % | K6: N | L6: % | M6: N | N6: % | O6: N | P6: % | Q6: N | R6: % | S6: N | T6: %
F7: Dutchess | G7: 6262 | H7: 3 | I7: 11055 | J7: 5.2 | K7: 52992 | L7: 25.1 | M7: 35689 | N7: 16.9 | O7: 21410 | P7: 10.1 | Q7: 44414 | R7: 21 | S7: 39558 | T7: 18.7
F8: Orange | G8: 10091 | H8: 3.9 | I8: 16609 | J8: 6.4 | K8: 72466 | L8: 28 | M8: 49355 | N8: 19.1 | O8: 26722 | P8: 10.3 | Q8: 46977 | R8: 18.2 | S8: 36412 | T8: 14.1
A9: Figure Rules | F9: Putnam | G9: 2255 | H9: 3.2 | I9: 2536 | J9: 3.6 | K9: 17647 | L9: 24.8 | M9: 11728 | N9: 16.5 | O9: 6002 | P9: 8.4 | Q9: 17222 | R9: 24.2 | S9: 13759 | T9: 19.3
A10: Figure Type | F10: Rockland | G10: 11800 | H10: 5.7 | I10: 13858 | J10: 6.6 | K10: 45118 | L10: 21.6 | M10: 33790 | N10: 16.2 | O10: 16169 | P10: 7.8 | Q10: 48405 | R10: 23.2 | S10: 39454 | T10: 18.9
A11: X Column | F11: Sullivan | G11: 2755 | H11: 4.9 | I11: 4129 | J11: 7.4 | K11: 16623 | L11: 29.8 | M11: 9973 | N11: 17.9 | O11: 5728 | P11: 10.3 | Q11: 9476 | R11: 17 | S11: 7077 | T11: 12.7
A12: Y Column | F12: Ulster | G12: 3463 | H12: 2.6 | I12: 7622 | J12: 5.7 | K12: 37570 | L12: 28 | M12: 22968 | N12: 17.1 | O12: 12934 | P12: 9.6 | Q12: 27094 | R12: 20.2 | S12: 22674 | T12: 16.9
A13: X Axis Title | F13: Westchester | G13: 37761 | H13: 5.4 | I13: 36459 | J13: 5.2 | K13: 124954 | L13: 17.9 | M13: 87534 | N13: 12.6 | O13: 44393 | P13: 6.4 | Q13: 181482 | R13: 26 | S13: 184619 | T13: 26.5
A14: Y Axis Title | F14: Mid-Hudson | G14: 74387 | H14: 4.5 | I14: 92268 | J14: 5.6 | K14: 367370 | L14: 22.4 | M14: 251037 | N14: 15.3 | O14: 133358 | P14: 8.1 | Q14: 375070 | R14: 22.9 | S14: 343553 | T14: 21
A15: Start at Zero | F15: NYS excl NYC | G15: 300738 | H15: 3.8 | I15: 403754 | J15: 5.1 | K15: 2039454 | L15: 25.8 | M15: 1277348 | N15: 16.2 | O15: 847708 | P15: 10.7 | Q15: 1643943 | R15: 20.8 | S15: 1392540 | T15: 17.6
F16: NYS | G16: 836124 | H16: 6 | I16: 862413 | J16: 6.2 | K16: 3437438 | L16: 24.6 | M16: 2081783 | N16: 14.9 | O16: 1242877 | P16: 8.9 | Q16: 3083769 | R16: 22 | S16: 2451734 | T16: 17.5
A18: Source Specifications
A19: Table ID
A20: URL
A21: Data Year
A22: Estimate Type
A23: Citation Month
A24: Citation Year
A25: Custom Text
A27: Note Specfications

Sheet Total Households
A1: Name | B1: Total Households, 2023
A2: Table/Figure/Both | B2: Table
A3: Object ID | B3: =IF($B$1="","",_xlfn.XLOOKUP($B$1,Master!$F$2:$F$308,Master!$G$2:$G$308,"")) -> tbl-households
G4: integer
A5: Table Rules | E5: Enter Data | G5: Households
A6: Multilevel Headers | B6: FALSE | F6: Dutchess | G6: 115184
F7: Orange | G7: 137311
F8: Putnam | G8: 35054
A9: Figure Rules | F9: Rockland | G9: 103284
A10: Figure Type | F10: Sullivan | G10: 30215
A11: X Column | F11: Ulster | G11: 73105
A12: Y Column | F12: Westchester | G12: 370256
A13: X Axis Title | F13: Mid-Hudson | G13: 864409
A14: Y Axis Title | F14: NYS excl NYC | G14: 4355640
A15: Start at Zero | F15: NYS | G15: 7668956
A18: Source Specifications
A19: Table ID
A20: URL
A21: Data Year
A22: Estimate Type
A23: Citation Month
A24: Citation Year
A25: Custom Text
A27: Note Specfications

Sheet Households by Income
A1: Name | B1: Households by Income, 2023
A2: Table/Figure/Both | B2: Table
A3: Object ID | B3: =IF($B$1="","",_xlfn.XLOOKUP($B$1,Master!$F$2:$F$308,Master!$G$2:$G$308,"")) -> tbl-income
G4: integer | H4: percent1 | I4: integer | J4: percent1 | K4: integer | L4: percent1 | M4: integer | N4: percent1 | O4: integer | P4: percent1 | Q4: integer | R4: percent1 | S4: integer | T4: percent1 | U4: integer | V4: percent1 | W4: integer | X4: percent1 | Y4: integer | Z4: percent1
A5: Table Rules | E5: Enter Data | F5: Area | G5: <$10,000 | I5: $10,000-$14,999 | K5: $15,000-$24,999 | M5: $25,000-$34,999 | O5: $35,000-$49,999 | Q5: $50,000-$74,999 | S5: $75,000-$99,999 | U5: $100,000-$149,999 | W5: $150,000-$199,999 | Y5: >$200,000
A6: Multilevel Headers | B6: TRUE | G6: Total Population | H6: % | I6: Total Population | J6: % | K6: Total Population | L6: % | M6: Total Population | N6: % | O6: Total Population | P6: % | Q6: Total Population | R6: % | S6: Total Population | T6: % | U6: Total Population | V6: % | W6: Total Population | X6: % | Y6: Total Population | Z6: %
F7: Dutchess | G7: 4723 | H7: 4.1 | I7: 2649 | J7: 2.3 | K7: 5298 | L7: 4.6 | M7: 6105 | N7: 5.3 | O7: 9906 | P7: 8.6 | Q7: 15780 | R7: 13.7 | S7: 14513 | T7: 12.6 | U7: 22346 | V7: 19.4 | W7: 13822 | X7: 12 | Y7: 20042 | Z7: 17.4
F8: Orange | G8: 5492 | H8: 4 | I8: 4119 | J8: 3 | K8: 8651 | L8: 6.3 | M8: 7003 | N8: 5.1 | O8: 10985 | P8: 8 | Q8: 18125 | R8: 13.2 | S8: 16340 | T8: 11.9 | U8: 27188 | V8: 19.8 | W8: 18125 | X8: 13.2 | Y8: 21421 | Z8: 15.6
A9: Figure Rules | F9: Putnam | G9: 841 | H9: 2.4 | I9: 631 | J9: 1.8 | K9: 1472 | L9: 4.2 | M9: 1402 | N9: 4 | O9: 2033 | P9: 5.8 | Q9: 3926 | R9: 11.2 | S9: 3365 | T9: 9.6 | U9: 7326 | V9: 20.9 | W9: 5503 | X9: 15.7 | Y9: 8553 | Z9: 24.4
A10: Figure Type | F10: Rockland | G10: 3822 | H10: 3.7 | I10: 2169 | J10: 2.1 | K10: 5784 | L10: 5.6 | M10: 5474 | N10: 5.3 | O10: 7746 | P10: 7.5 | Q10: 11878 | R10: 11.5 | S10: 10328 | T10: 10 | U10: 18281 | V10: 17.7 | W10: 12394 | X10: 12 | Y10: 25408 | Z10: 24.6
A11: X Column | F11: Sullivan | G11: 1420 | H11: 4.7 | I11: 1481 | J11: 4.9 | K11: 2327 | L11: 7.7 | M11: 2447 | N11: 8.1 | O11: 3384 | P11: 11.2 | Q11: 5137 | R11: 17 | S11: 3807 | T11: 12.6 | U11: 4442 | V11: 14.7 | W11: 2478 | X11: 8.2 | Y11: 3293 | Z11: 10.9
A12: Y Column | F12: Ulster | G12: 4021 | H12: 5.5 | I12: 2778 | J12: 3.8 | K12: 4606 | L12: 6.3 | M12: 4752 | N12: 6.5 | O12: 7384 | P12: 10.1 | Q12: 10527 | R12: 14.4 | S12: 8334 | T12: 11.4 | U12: 13378 | V12: 18.3 | W12: 7384 | X12: 10.1 | Y12: 9942 | Z12: 13.6
A13: X Axis Title | F13: Westchester | G13: 17402 | H13: 4.7 | I13: 9997 | J13: 2.7 | K13: 17032 | L13: 4.6 | M13: 15180 | N13: 4.1 | O13: 27029 | P13: 7.3 | Q13: 37766 | R13: 10.2 | S13: 36285 | T13: 9.8 | U13: 59241 | V13: 16 | W13: 39988 | X13: 10.8 | Y13: 110336 | Z13: 29.8
A14: Y Axis Title | F14: Mid-Hudson | G14: 37721 | H14: 4.4 | I14: 23824 | J14: 2.8 | K14: 45169 | L14: 5.2 | M14: 42364 | N14: 4.9 | O14: 68467 | P14: 7.9 | Q14: 103139 | R14: 11.9 | S14: 92973 | T14: 10.8 | U14: 152202 | V14: 17.6 | W14: 99694 | X14: 11.5 | Y14: 198996 | Z14: 23
A15: Start at Zero | F15: NYS excl NYC | G15: 201885 | H15: 4.6 | I15: 142135 | J15: 3.3 | K15: 266550 | L15: 6.1 | M15: 266736 | N15: 6.1 | O15: 402990 | P15: 9.3 | Q15: 617645 | R15: 14.2 | S15: 516423 | T15: 11.9 | U15: 781447 | V15: 17.9 | W15: 466426 | X15: 10.7 | Y15: 701072 | Z15: 16.1
F16: NYS | G16: 437130 | H16: 5.7 | I16: 314427 | J16: 4.1 | K16: 498482 | L16: 6.5 | M16: 475475 | N16: 6.2 | O16: 697875 | P16: 9.1 | Q16: 1058316 | R16: 13.8 | S16: 874261 | T16: 11.4 | U16: 1288385 | V16: 16.8 | W16: 774565 | X16: 10.1 | Y16: 1257709 | Z16: 16.4
A18: Source Specifications
A19: Table ID
A20: URL
A21: Data Year
A22: Estimate Type
A23: Citation Month
A24: Citation Year
A25: Custom Text
A27: Note Specfications

Sheet Veteran Status-Population
A1: Name | B1: Population by Veteran Status, 2023
A2: Table/Figure/Both | B2: Table
A3: Object ID | B3: =IF($B$1="","",_xlfn.XLOOKUP($B$1,Master!$F$2:$F$308,Master!$G$2:$G$308,"")) -> tbl-veteran
G4: integer | H4: integer | I4: percent1
A5: Table Rules | E5: Enter Data | F5: Area | G5: Civilian Population 18 Years and Older | H5: Civilian Veterans
A6: Multilevel Headers | B6: TRUE | G6: Total Population | H6: Total Population | I6: %
F7: Dutchess | G7: 241517 | H7: 11694 | I7: 4.8
F8: Orange | G8: 296319 | H8: 16695 | I8: 5.6
A9: Figure Rules | F9: Putnam | G9: 78712 | H9: 3320 | I9: 4.2
A10: Figure Type | F10: Rockland | G10: 239088 | H10: 7130 | I10: 3
A11: X Column | F11: Sullivan | G11: 62181 | H11: 3713 | I11: 6
A12: Y Column | F12: Ulster | G12: 150409 | H12: 6711 | I12: 4.5
A13: X Axis Title | F13: Westchester | G13: 781837 | H13: 23744 | I13: 3
A14: Y Axis Title | F14: Mid-Hudson | G14: 1850063 | H14: 73007 | I14: 3.9
A15: Start at Zero | F15: NYS excl NYC | G15: 8964773 | H15: 478417 | I15: 5.3
F16: NYS | G16: 15737168 | H16: 607728 | I16: 3.9
A18: Source Specifications
A19: Table ID
A20: URL
A21: Data Year
A22: Estimate Type
A23: Citation Month
A24: Citation Year
A25: Custom Text
A27: Note Specfications

Sheet Type of Disability-Population
A1: Name | B1: Percentage of Population by Type of Disability, 2023
A2: Table/Figure/Both | B2: Table
A3: Object ID | B3: =IF($B$1="","",_xlfn.XLOOKUP($B$1,Master!$F$2:$F$308,Master!$G$2:$G$308,"")) -> tbl-disability
G4: percent1 | H4: percent1 | I4: percent1 | J4: percent1 | K4: percent1 | L4: percent1 | M4: percent1
A5: Table Rules | E5: Enter Data | G5: Total with Any Disability | H5: Hearing Difficulty | I5: Vision Difficulty | J5: Cognitive Difficulty | K5: Ambulatory Difficulty | L5: Self-Care Difficulty | M5: Independent Living Difficulty
A6: Multilevel Headers | B6: FALSE | F6: Dutchess | G6: 12.2 | H6: 3.5 | I6: 2 | J6: 4.7 | K6: 6.3 | L6: 2.6 | M6: 5.9
F7: Orange | G7: 11.7 | H7: 3.2 | I7: 2.1 | J7: 5.4 | K7: 6.3 | L7: 2.9 | M7: 6.2
F8: Putnam | G8: 9.6 | H8: 2.8 | I8: 1.4 | J8: 3.5 | K8: 5.4 | L8: 2.4 | M8: 4.6
A9: Figure Rules | F9: Rockland | G9: 8.7 | H9: 2.7 | I9: 1.4 | J9: 3.4 | K9: 4.4 | L9: 2.2 | M9: 4.5
A10: Figure Type | F10: Sullivan | G10: 15.9 | H10: 4.4 | I10: 3 | J10: 6.4 | K10: 9.1 | L10: 3.7 | M10: 7.2
A11: X Column | F11: Ulster | G11: 14.4 | H11: 4.2 | I11: 2.3 | J11: 5.1 | K11: 7.4 | L11: 3 | M11: 6
A12: Y Column | F12: Westchester | G12: 9.5 | H12: 2.5 | I12: 1.6 | J12: 3.7 | K12: 5.3 | L12: 2.3 | M12: 4.8
A13: X Axis Title | F13: Mid-Hudson | G13: 10.2 | H13: 2.8 | I13: 1.7 | J13: 3.8 | K13: 5.2 | L13: 2.3 | M13: 3.9
A14: Y Axis Title | F14: NYS | G14: 11.6 | H14: 2.8 | I14: 2.1 | J14: 4.5 | K14: 6.6 | L14: 2.7 | M14: 5.7
A15: Start at Zero
A18: Source Specifications
A19: Table ID
A20: URL
A21: Data Year
A22: Estimate Type
A23: Citation Month
A24: Citation Year
A25: Custom Text
A27: Note Specfications

Sheet No Vehicle
A1: Name | B1: Percentage of Households with No Vehicles Available, 2021–2023
A2: Table/Figure/Both | B2: Figure
A3: Object ID | B3: =IF($B$1="","",_xlfn.XLOOKUP($B$1,Master!$F$2:$F$308,Master!$G$2:$G$308,"")) -> tbl-no-vehicles
A4: Figure ID | B4: =IF($B$1="","",_xlfn.XLOOKUP($B$1,Master!$F$2:$F$308,Master!$H$2:$H$308,"")) -> fig-no-vehicles | F4: integer | G4: percent1 | H4: percent1 | I4: percent1 | J4: percent1 | K4: percent1 | L4: percent1 | M4: percent1 | N4: percent1
A5: Table Rules | E5: Enter Data | F5: Year | G5: Dutchess | H5: Orange | I5: Putnam | J5: Rockland | K5: Sullivan | L5: Ulster | M5: Westchester | N5: NYS
A6: Multilevel Headers | B6: FALSE | F6: 2017–2021 | G6: 7.2 | H6: 8.9 | I6: 4.7 | J6: 10.4 | K6: 10.4 | L6: 6.8 | M6: 14.3 | N6: 28.9
F7: 2018–2022 | G7: 7.2 | H7: 8.6 | I7: 4.1 | J7: 9.9 | K7: 9.9 | L7: 7.2 | M7: 14.2 | N7: 29
F8: 2019–2023 | G8: 7 | H8: 8.6 | I8: 4.2 | J8: 9.7 | K8: 8.8 | L8: 7.5 | M8: 14.2 | N8: 29
A9: Figure Rules
A10: Figure Type | B10: Line
A11: X Column | B11: Year
A12: Y Column | B12: Percent
A13: X Axis Title | B13: =F5 -> Year
A14: Y Axis Title | B14: Percent
A15: Start at Zero | B15: TRUE
A18: Source Specifications
A19: Table ID
A20: URL | B20: https://data.census.gov/table/ACSDP5Y2022.DP04?q=dp04&g=050XX00US36105,36027,36071,36119,36087,36079,36111_04 0XX00US36
A21: Data Year | B21: 2021–2023
A22: Estimate Type
A23: Citation Month | B23: April
A24: Citation Year | B24: 2025
A25: Custom Text
A27: Note Specifications
A28: The American Community Survey asks respondents how many automobiles, vans, and trucks of one-ton capacity or less are kept at home for use by members of the household. 2023 ACS includes 2019–2023

Sheet Mode To Work
A1: Name | B1: Percentage of Workers by Mode of Transportation to Work, 2023
A2: Table/Figure/Both | B2: Figure
A3: Object ID | B3: =IF($B$1="","",_xlfn.XLOOKUP($B$1,Master!$F$2:$F$308,Master!$G$2:$G$308,"")) -> tbl-mode-to-work
A4: Figure ID | B4: =IF($B$1="","",_xlfn.XLOOKUP($B$1,Master!$F$2:$F$308,Master!$H$2:$H$308,"")) -> fig-mode-to-work | G4: percent1 | H4: percent1 | I4: percent1 | J4: percent1 | K4: percent1 | L4: percent1 | M4: percent1 | N4: percent1
A5: Table Rules | E5: Enter Data | G5: Dutchess | H5: Orange | I5: Putnam | J5: Rockland | K5: Sullivan | L5: Ulster | M5: Westchester | N5: NYS
A6: Multilevel Headers | B6: FALSE | F6: Drove Alone | G6: 71.4 | H6: 69.8 | I6: 70.6 | J6: 66.6 | K6: 74.1 | L6: 71.7 | M6: 51.9 | N6: 50
F7: Carpooled | G7: 7.5 | H7: 9.6 | I7: 7.6 | J7: 8.5 | K7: 8.8 | L7: 6.7 | M7: 7.2 | N7: 6.3
F8: Public transportation | G8: 3.7 | H8: 4.4 | I8: 5.6 | J8: 6.2 | K8: 1.2 | L8: 2.1 | M8: 17.8 | N8: 22.4
A9: Figure Rules | F9: Walked | G9: 2.3 | H9: 3.1 | I9: 1.5 | J9: 3.1 | K9: 2.4 | L9: 2.4 | M9: 3.7 | N9: 5.3
A10: Figure Type | B10: Clustered Bar | F10: Taxicab, motorcycle, bicycle, or other means | G10: 1.7 | H10: 2 | I10: 1 | J10: 2.8 | K10: 1.9 | L10: 1.8 | M10: 2.1 | N10: 2.6
A11: X Column | B11: Category | F11: Worked from home | G11: 13.4 | H11: 11.1 | I11: 13.7 | J11: 12.7 | K11: 11.6 | L11: 15.3 | M11: 17.3 | N11: 13.3
A12: Y Column | B12: Percent
A13: X Axis Title
A14: Y Axis Title | B14: Percent
A15: Start at Zero | B15: TRUE
A18: Source Specifications
A19: Table ID
A20: URL | B20: https://data.census.gov/table/ACSDT5Y2023.B08141?q=b08141&g=050XX00US36105,36027,36071,36119,36087,36079,3611 1_040XX00US36
A21: Data Year | B21: 2023
A22: Estimate Type
A23: Citation Month | B23: April
A24: Citation Year | B24: 2025
A25: Custom Text
A27: Note Specifications
A28: The American Community Survey asks respondents how they usually got to work last week. For respondents who use multiple transportation modes they are restricted to the single method of transportation used for the longest distance. 2023 ACS includes 2019–2023

Sheet Mean Time Work
A1: Name | B1: Mean Travel Time to Work, 2021–2023
A2: Table/Figure/Both | B2: Figure
A3: Object ID | B3: =IF($B$1="","",_xlfn.XLOOKUP($B$1,Master!$F$2:$F$308,Master!$G$2:$G$308,"")) -> tbl-mean-time-work
A4: Figure ID | B4: =IF($B$1="","",_xlfn.XLOOKUP($B$1,Master!$F$2:$F$308,Master!$H$2:$H$308,"")) -> fig-mean-time-work | F4: integer | G4: percent1 | H4: percent1 | I4: percent1 | J4: percent1 | K4: percent1 | L4: percent1 | M4: percent1 | N4: percent1
A5: Table Rules | E5: Enter Data | G5: Dutchess | H5: Orange | I5: Putnam | J5: Rockland | K5: Sullivan | L5: Ulster | M5: Westchester | N5: NYS
A6: Multilevel Headers | B6: FALSE | F6: 2017–2021 | G6: 32 | H6: 34.1 | I6: 39.2 | J6: 31.2 | K6: 28.6 | L6: 28.6 | M6: 34.8 | N6: 33.3
F7: 2018–2022 | G7: 32.3 | H7: 34.1 | I7: 39.9 | J7: 31 | K7: 28.1 | L7: 28.1 | M7: 34.8 | N7: 33.2
F8: 2019–2023 | G8: 31.4 | H8: 34.2 | I8: 39.5 | J8: 30.3 | K8: 27.8 | L8: 27.8 | M8: 34.7 | N8: 32.8
A9: Figure Rules
A10: Figure Type | B10: Line
A11: X Column | B11: Period
A12: Y Column | B12: Minutes
A13: X Axis Title
A14: Y Axis Title | B14: Minutes
A15: Start at Zero | B15: TRUE
A18: Source Specifications
A19: Table ID
A20: URL | B20: https://data.census.gov/table/ACSDP5Y2023.DP03?q=DP03&g=050XX00US36105,36027,36071,36119,36087,36079,36111_04 0XX00US36
A21: Data Year | B21: 2021–2023
A22: Estimate Type
A23: Citation Month | B23: April
A24: Citation Year | B24: 2025
A25: Custom Text
A27: Note Specifications
A28: The American Community Survey asks respondents in the workforce how many minutes it usually takes them to get from home to work. The travel time refers to a one-way trip on a typical day. This includes time spent waiting for public transportation, picking up passengers in carpools, and time spent in other activities related to getting to work. Sullivan County and Ulster County do have the same data according to the Census. 2023 ACS includes 2019–2023.

Sheet DC Top Affect Health
A1: Name | B1: Top Rated Issues That Affect Health in Dutchess County (n = 109)
A2: Table/Figure/Both | B2: Figure
A3: Object ID | B3: =IF($B$1="","",_xlfn.XLOOKUP($B$1,Master!$F$2:$F$308,Master!$G$2:$G$308,"")) -> tbl-DC-affect-health
A4: Figure ID | B4: =IF($B$1="","",_xlfn.XLOOKUP($B$1,Master!$F$2:$F$308,Master!$H$2:$H$308,"")) -> fig-DC-affect-health | F4: percent1 | G4: percent1 | H4: percent1 | I4: percent1 | J4: percent1 | K4: percent1 | L4: percent1 | M4: percent1 | N4: percent1 | O4: percent1
A5: Table Rules | E5: Enter Data | F5: Access to affordable, nutritious food | G5: Access to mental health providers | H5: Access to affordable, decent and safe housing | I5: Access to specialty services/providers | J5: Access to affordable, reliable transportation | K5: Access to affordable health insurance | L5: Access to medical providers | M5: Access to culturally sensitive health care providers | N5: Access to high quality education | O5: Access to clean water and non-polluted air
A6: Multilevel Headers | B6: FALSE | F6: 48.6 | G6: 47.7 | H6: 46.8 | I6: 42.2 | J6: 40.4 | K6: 34.9 | L6: 18.4 | M6: 12 | N6: 8.3 | O6: 0.9
A9: Figure Rules
A10: Figure Type | B10: Bar
A11: X Column | B11: Category
A12: Y Column | B12: Percent
A13: X Axis Title
A14: Y Axis Title | B14: Percent
A15: Start at Zero | B15: TRUE
A18: Source Specifications
A19: Table ID
A20: URL
A21: Data Year
A22: Estimate Type
A23: Citation Month
A24: Citation Year
A25: Custom Text
A27: Note Specifications

Sheet DC Top Barriers
A1: Name | B1: Top Rated Barriers to Achieving Better Health in Dutchess County (n = 109)
A2: Table/Figure/Both | B2: Figure
A3: Object ID | B3: =IF($B$1="","",_xlfn.XLOOKUP($B$1,Master!$F$2:$F$308,Master!$G$2:$G$308,"")) -> tbl-DC-achieve-health
A4: Figure ID | B4: =IF($B$1="","",_xlfn.XLOOKUP($B$1,Master!$F$2:$F$308,Master!$H$2:$H$308,"")) -> fig-DC-achieve-health | F4: percent1 | G4: percent1 | H4: percent1 | I4: percent1 | J4: percent1 | K4: percent1 | L4: percent1 | M4: percent1 | N4: percent1 | O4: percent1 | P4: percent1 | Q4: percent1
A5: Table Rules | E5: Enter Data | F5: Knowledge of existing resources | G5: Health literacy | H5: Geographic location living in a rural area | I5: Having someone to help them understand their medical condition | J5: Having someone help them understand insurance | K5: Substance Use Disorder (SUD) or Alcohol Use Disorder (AUD) | L5: Other | M5: Geographic location- living in an urban area | N5: Attainment of education | O5: Having a safe place to play and/or exercise | P5: Quality of education | Q5: Cultural customs
A6: Multilevel Headers | B6: FALSE | F6: 77.1 | G6: 51.4 | H6: 34.9 | I6: 32.1 | J6: 25.7 | K6: 25.7 | L6: 17.4 | M6: 9.2 | N6: 7.3 | O6: 6.4 | P6: 6.4 | Q6: 6.4
A9: Figure Rules
A10: Figure Type | B10: Bar
A11: X Column | B11: Category
A12: Y Column | B12: Percent
A13: X Axis Title
A14: Y Axis Title | B14: Percent
A15: Start at Zero | B15: TRUE
A18: Source Specifications
A19: Table ID
A20: URL
A21: Data Year
A22: Estimate Type
A23: Citation Month
A24: Citation Year
A25: Custom Text
A27: Note Specifications

Sheet DC Impact Health
A1: Name | B1: The Impact of Health Issues in Dutchess County (n = 106)
A2: Table/Figure/Both | B2: Both
A3: Object ID | B3: =IF($B$1="","",_xlfn.XLOOKUP($B$1,Master!$F$2:$F$308,Master!$G$2:$G$308,"")) -> tbl-DC-impact-hlth-issue
A4: Figure ID | B4: =IF($B$1="","",_xlfn.XLOOKUP($B$1,Master!$F$2:$F$308,Master!$H$2:$H$308,"")) -> fig-DC-impact-hlth-issue | G4: percent1 | H4: percent1 | I4: percent1 | J4: percent1 | K4: percent1 | L4: percent1
